<robot name="test_robot">
	<!-- base height : 0.04m base width: 0.115m base depth: 0.115m base_arm_1 
		width 0.1m base_arm_1 depth: 0.03m base_arm_1 heigth: 0.03m base_arm_2 length: 
		0.08m lowerarm length: 0.17m lowerarm width: 0.03m lowerarm heigth: 0.04m 
		middle_arm: 0.075m middle_arm_wrist offset 0.025 gripper length 0.17m mountplate 
		0.08m width: 0.05m -->
	<link name="base">
		<visual>
			<origin xyz="0 0 0.02" rpy="0 0 0" />
			<geometry>
				<box size="0.115 0.115 0.04" />
			</geometry>
			<material name="red">
				<color rgba="1 0 0 1" />
			</material>
		</visual>
	</link>
	
	<joint name="joint1" type="revolute">
		<limit effort="1000.0" lower="-1.3" upper="1.3" velocity="0.2" />
		<parent link="base" />
		<child link="base_arm" />
		<origin xyz=" 0 0 0.04" rpy="0 0 0" />
		<axis xyz="0 0 1" />
	</joint>

	
	
	<!-- The rotating base -->
	<link name="base_arm">
		<visual>
			<origin xyz="0 0 0.09" rpy="0 0 0" />
			<geometry>
				<box size="0.03 0.03 0.18 "/>
			</geometry>
			<material name="white">
				<color rgba="1 1 1 1" />
			</material>
		</visual>
	</link>


	<joint name="joint2" type="revolute">
		<limit effort="1000.0" lower="-2.48" upper="2.48" velocity="0.2" />
		<parent link="base_arm" />
		<child link="lower_arm" />
		<origin xyz="0 0 0.15" rpy="1.5707 -1.5707 0" />
		<axis xyz="0 0 1" />
	</joint>
	

	<link name="lower_arm">
		<visual>
			<origin xyz="0.085 0 0 " rpy="0 0 0" />
			<geometry>
				<box size="0.17 0.03 0.03"></box>
			</geometry>
			<material name="cyan">
				<color rgba="0 1 1 1" />
			</material>
		</visual>
	</link>


	<joint name="joint3" type="revolute">
		<limit effort="1000.0" lower="-2.48" upper="2.48" velocity="0.2" />
		<parent link="lower_arm" />
		<child link="middle_arm" />
		<origin xyz="0.17 0 0" rpy="0 0 0" />
		<axis xyz="0 0 1" />
	</joint>

	
	<link name="middle_arm">
		<visual>
			<origin xyz="0.015 0 0 " rpy="0 0 0" />
			<geometry>
				<box size="0.03 0.03 0.11" ></box>
			</geometry>
			<material name="blue">
				<color rgba="0 0 1 1" />
			</material>
		</visual>
	</link>


	<joint name="wrist_linkage" type="fixed">
		<parent link="middle_arm" />
		<child link="wrist_temp" />
		<origin xyz="0.03 0.0 0" rpy="0 0 0" />
	</joint>	

	
	<link name="wrist_temp">
		<visual>
			<origin xyz="0.015 0.02125 0" rpy="0 0 0" />
			<geometry>
				<box size="0.03 0.045 0.03"></box>
			</geometry>
			<material name="white">
				<color rgba="0.2 0.2 0.2 1" />
			</material>
		</visual>
	</link>
	
	<joint name="joint4" type="revolute">
		<limit effort="1000.0" lower="-2.48" upper="2.48" velocity="0.2" />
		<parent link="wrist_temp" />
		<child link="wrist" />
		<origin xyz="0.035 0.025 0" rpy="0 1.5707 0" />
		<axis xyz="0 0 1" />
	</joint>

	<link name="wrist">
		<visual>
			<origin xyz=" -0.02 0 0.025 " rpy="0 0 0" />
			<geometry>
				<box size="0.08 0.005 0.05"></box>
			</geometry>
			<material name="white">
				<color rgba="1 1 1 1" />
			</material>
		</visual>
	</link>

	 <joint name="gripper_linkage_cameraplate" type="fixed">
		<parent link="wrist" />
		<child link="gripper_camera_plate" />
		<origin xyz="0 0.0 0.001" rpy="0 0 0" />
	</joint>
	
	
	<link name="gripper_camera_plate">
		<visual>
			<origin xyz="0 0.03 0" rpy="0 0 0" />
			<geometry>
				<box size="0.05 0.06 0.005"></box>
			</geometry>
			<material name="yellow">
				<color rgba="1 0 1 1" />r
			</material>
		</visual>
	</link> 
	
	<joint name="gripper_linkage_servo" type="fixed">
		<parent link="gripper_camera_plate" />
		<child link="gripper_servo_base" />
		<origin xyz="-0.025 -0.015 0.025" rpy="0 0 0" />
	</joint>
	
	<link name="gripper_servo_base">
		<visual>
			<origin xyz="0 0 0 " rpy="0 0 0" />
			<geometry>
				<box size=" 0.045 0.03 0.03 "></box>
			</geometry>
			<material name="white">
				<color rgba="1 0 0 1" />
			</material>
		</visual>
	</link>

	<joint name="gripper_linkage_end_effector" type="fixed">
		<parent link="gripper_servo_base" />
		<child link="gripper_end_effector" />
		<origin xyz="0.025 0.015 0.15" rpy="0 0 0" />
	</joint>

	<link name="gripper_end_effector">
		<visual>
			<origin xyz="0 0 -0.075 " rpy="0 0 0" />
			<geometry>
				<box size=" 0.03 0.03 0.15 "></box>
			</geometry>
			<material name="grey">
				<color rgba="0.5 0.3 0.9 1" />
			</material>
		</visual>
	</link>
<!-- 
	<link name="gripper_left_finger">
	
	</link>

	<link name="gripper_right_finger">
	
	</link> -->
</robot>
